Workbook

Sheet 📊 Dashboard
B2: MONTHLY BUDGET TRACKER
B3: Track • Plan • Grow Your Wealth with AI-Powered Insights
B4: Personal Finance Coach & Educator | AI-Powered Finance Education | yourwebsite.ca
B7: Select Month: | D7: January | E7: ← Change month in Budget Input sheet
B9: Total Income | C9: Total Expenses | D9: Net Savings | E9: Savings Rate
B10: ='📥 Income'!D33 -> 0 | C10: ='💸 Expenses'!D62 -> 0 | D10: =B10-C10 -> 0 | E10: =IFERROR(D10/B10,0) -> 0
B13: BUDGET SUMMARY
B14: Category | C14: Budget ($) | D14: Actual ($) | E14: Variance ($) | F14: % Used
B15: Total Income | C15: ='📥 Income'!C33 -> 0 | D15: ='📥 Income'!D33 -> 0 | E15: =D15-C15 -> 0 | F15: =IFERROR(D15/C15,0) -> 0
B16: Housing | C16: ='💸 Expenses'!C14 -> 0 | D16: ='💸 Expenses'!D14 -> 0 | E16: =D16-C16 -> 0 | F16: =IFERROR(D16/C16,0) -> 0
B17: Transportation | C17: ='💸 Expenses'!C23 -> 0 | D17: ='💸 Expenses'!D23 -> 0 | E17: =D17-C17 -> 0 | F17: =IFERROR(D17/C17,0) -> 0
B18: Food & Dining | C18: ='💸 Expenses'!C30 -> 0 | D18: ='💸 Expenses'!D30 -> 0 | E18: =D18-C18 -> 0 | F18: =IFERROR(D18/C18,0) -> 0
B19: Health & Wellness | C19: ='💸 Expenses'!C37 -> 0 | D19: ='💸 Expenses'!D37 -> 0 | E19: =D19-C19 -> 0 | F19: =IFERROR(D19/C19,0) -> 0
B20: Personal & Lifestyle | C20: ='💸 Expenses'!C46 -> 0 | D20: ='💸 Expenses'!D46 -> 0 | E20: =D20-C20 -> 0 | F20: =IFERROR(D20/C20,0) -> 0
B21: Savings & Investing | C21: ='💸 Expenses'!C54 -> 0 | D21: ='💸 Expenses'!D54 -> 0 | E21: =D21-C21 -> 0 | F21: =IFERROR(D21/C21,0) -> 0
B22: Total Expenses | C22: ='💸 Expenses'!C62 -> 0 | D22: ='💸 Expenses'!D62 -> 0 | E22: =D22-C22 -> 0 | F22: =IFERROR(D22/C22,0) -> 0
B23: NET SAVINGS | C23: =C15-C22 -> 0 | D23: =D15-D22 -> 0 | E23: =D23-C23 -> 0 | F23: =IFERROR(D23/C15,0) -> 0
B26: HOW TO USE THIS TEMPLATE
B27: 1. Go to the 📥 Income sheet and enter your monthly income sources.
B28: 2. Go to the 💸 Expenses sheet and enter budget amounts AND actual spending.
B29: 3. This Dashboard updates automatically — your summary and savings rate refresh instantly.
B30: 4. Blue cells = your inputs. Black cells = formulas (do not edit).
B31: 5. Use the 📈 Charts sheet to visualize your spending breakdown.
B34: EDUCATIONAL USE DISCLAIMER
B35: ⚠️ DISCLAIMER: This template is for educational and informational purposes only.
B36: It does not constitute personalized financial, investment, tax, or legal advice.
B37: Consult a registered financial advisor for advice specific to your situation.
B38: © Your Personal Finance Coach | AI-Powered Finance Education | yourwebsite.ca

Sheet 📥 Income
B2: INCOME TRACKER
B3: For educational use only — see disclaimer at bottom of this sheet
B6: Month: | D6: January
B8: EMPLOYMENT INCOME
B9: Income Source | C9: Budgeted ($) | D9: Actual ($) | E9: Variance ($)
B10: Primary Salary / Wages (after tax) | E10: =D10-C10 -> 0
B11: Secondary Job / Part-time Income | E11: =D11-C11 -> 0
B12: Bonuses / Commissions | E12: =D12-C12 -> 0
B13: Overtime Pay | E13: =D13-C13 -> 0
B14: Employment Subtotal | C14: =SUM(C10:C13) -> 0 | D14: =SUM(D10:D13) -> 0 | E14: =D14-C14 -> 0
B16: GOVERNMENT & BENEFITS
B17: Income Source | C17: Budgeted ($) | D17: Actual ($) | E17: Variance ($)
B18: EI Benefits | E18: =D18-C18 -> 0
B19: CPP / OAS | E19: =D19-C19 -> 0
B20: Child Tax Benefit (CCB) | E20: =D20-C20 -> 0
B21: GST/HST Credit | E21: =D21-C21 -> 0
B22: Provincial Benefits | E22: =D22-C22 -> 0
B23: Government Subtotal | C23: =SUM(C18:C22) -> 0 | D23: =SUM(D18:D22) -> 0 | E23: =D23-C23 -> 0
B25: OTHER INCOME
B26: Income Source | C26: Budgeted ($) | D26: Actual ($) | E26: Variance ($)
B27: Rental Income | E27: =D27-C27 -> 0
B28: Side Business / Freelance | E28: =D28-C28 -> 0
B29: Investment Dividends / Interest | E29: =D29-C29 -> 0
B30: Other Income | E30: =D30-C30 -> 0
B31: Other Subtotal | C31: =SUM(C27:C30) -> 0 | D31: =SUM(D27:D30) -> 0 | E31: =D31-C31 -> 0
B33: TOTAL INCOME | C33: =C14+C23+C31 -> 0 | D33: =D14+D23+D31 -> 0 | E33: =E14+E23+E31 -> 0
B35: 💡 Tip: Enter your NET (after-tax) income amounts. If self-employed, use gross and track taxes separately.
B38: EDUCATIONAL USE DISCLAIMER
B39: ⚠️ DISCLAIMER: This template is for educational and informational purposes only.
B40: It does not constitute personalized financial, investment, tax, or legal advice.
B41: Consult a registered financial advisor for advice specific to your situation.
B42: © Your Personal Finance Coach | AI-Powered Finance Education | yourwebsite.ca

Sheet 💸 Expenses
B2: EXPENSE TRACKER
B3: For educational use only — see disclaimer at bottom of this sheet
B6: HOUSING & UTILITIES
B7: Expense Item | C7: Budgeted ($) | D7: Actual ($) | E7: Variance ($)
B8: Rent / Mortgage Payment | E8: =D8-C8 -> 0
B9: Property Tax (monthly portion) | E9: =D9-C9 -> 0
B10: Home Insurance | E10: =D10-C10 -> 0
B11: Electricity / Gas | E11: =D11-C11 -> 0
B12: Water / Internet / Cable | E12: =D12-C12 -> 0
B13: Home Maintenance / Repairs | E13: =D13-C13 -> 0
B14: HOUSING & UTILITIES Subtotal | C14: =SUM(C8:C13) -> 0 | D14: =SUM(D8:D13) -> 0 | E14: =D14-C14 -> 0
B15: TRANSPORTATION
B16: Expense Item | C16: Budgeted ($) | D16: Actual ($) | E16: Variance ($)
B17: Car Payment / Lease | E17: =D17-C17 -> 0
B18: Gas / Fuel | E18: =D18-C18 -> 0
B19: Car Insurance | E19: =D19-C19 -> 0
B20: Public Transit / Uber | E20: =D20-C20 -> 0
B21: Parking | E21: =D21-C21 -> 0
B22: Vehicle Maintenance | E22: =D22-C22 -> 0
B23: TRANSPORTATION Subtotal | C23: =SUM(C17:C22) -> 0 | D23: =SUM(D17:D22) -> 0 | E23: =D23-C23 -> 0
B24: FOOD & DINING
B25: Expense Item | C25: Budgeted ($) | D25: Actual ($) | E25: Variance ($)
B26: Groceries | E26: =D26-C26 -> 0
B27: Restaurants / Takeout | E27: =D27-C27 -> 0
B28: Coffee / Snacks | E28: =D28-C28 -> 0
B29: Meal Kits / Delivery Apps | E29: =D29-C29 -> 0
B30: FOOD & DINING Subtotal | C30: =SUM(C26:C29) -> 0 | D30: =SUM(D26:D29) -> 0 | E30: =D30-C30 -> 0
B31: HEALTH & WELLNESS
B32: Expense Item | C32: Budgeted ($) | D32: Actual ($) | E32: Variance ($)
B33: Health / Dental / Vision Insurance | E33: =D33-C33 -> 0
B34: Prescriptions / Pharmacy | E34: =D34-C34 -> 0
B35: Gym / Fitness | E35: =D35-C35 -> 0
B36: Medical Appointments | E36: =D36-C36 -> 0
B37: HEALTH & WELLNESS Subtotal | C37: =SUM(C33:C36) -> 0 | D37: =SUM(D33:D36) -> 0 | E37: =D37-C37 -> 0
B38: PERSONAL & LIFESTYLE
B39: Expense Item | C39: Budgeted ($) | D39: Actual ($) | E39: Variance ($)
B40: Clothing & Shoes | E40: =D40-C40 -> 0
B41: Personal Care / Grooming | E41: =D41-C41 -> 0
B42: Entertainment / Subscriptions | E42: =D42-C42 -> 0
B43: Gifts & Donations | E43: =D43-C43 -> 0
...

Sheet 📈 Charts
B2: SPENDING BREAKDOWN & VISUAL SUMMARY
B3: Charts update automatically from your Income and Expense sheets
B6: EXPENSE CATEGORY SUMMARY
B7: Category | C7: Budgeted ($) | D7: Actual ($)
B8: Housing & Utilities | C8: ='💸 Expenses'!C14 -> 0 | D8: ='💸 Expenses'!D14 -> 0
B9: Transportation | C9: ='💸 Expenses'!C23 -> 0 | D9: ='💸 Expenses'!D23 -> 0
B10: Food & Dining | C10: ='💸 Expenses'!C30 -> 0 | D10: ='💸 Expenses'!D30 -> 0
B11: Health & Wellness | C11: ='💸 Expenses'!C37 -> 0 | D11: ='💸 Expenses'!D37 -> 0
B12: Personal & Lifestyle | C12: ='💸 Expenses'!C46 -> 0 | D12: ='💸 Expenses'!D46 -> 0
B13: Savings & Investing | C13: ='💸 Expenses'!C54 -> 0 | D13: ='💸 Expenses'!D54 -> 0
B14: Debt Repayment | C14: ='💸 Expenses'!C61 -> 0 | D14: ='💸 Expenses'!D61 -> 0
B15: TOTAL | C15: =SUM(C8:C14) -> 0 | D15: =SUM(D8:D14) -> 0
B18: MONTHLY FINANCIAL HEALTH
B19: Total Income | C19: Budget | D19: ='📥 Income'!D33 -> 0
B20: Total Expenses | C20: Budget | D20: ='💸 Expenses'!D62 -> 0
B21: Net Savings | C21: Budget | D21: =D19-D20 -> 0
B22: Savings Rate | C22: Budget | D22: =IFERROR(D21/D19,0) -> 0
B23: Monthly Goal | C23: Budget
B28: EDUCATIONAL USE DISCLAIMER
B29: ⚠️ DISCLAIMER: This template is for educational and informational purposes only.
B30: It does not constitute personalized financial, investment, tax, or legal advice.
B31: Consult a registered financial advisor for advice specific to your situation.
B32: © Your Personal Finance Coach | AI-Powered Finance Education | yourwebsite.ca

Sheet 🍁 Canada Tips
B2: CANADIAN SAVINGS ACCOUNTS — QUICK REFERENCE
B3: 2025 Limits & Key Rules for Canadian Residents
B6: TFSA – Tax-Free Savings Account
B7: 2025 annual limit: $7,000
B8: Contributions not tax-deductible; growth and withdrawals are 100% tax-free.
B9: Withdrawn amounts are re-added to room the following January.
B10: Anyone 18+ who is a Canadian resident can contribute.
B12: RRSP – Registered Retirement Savings Plan
B13: 2025 annual limit: 18% of prior year earned income, max $32,490
B14: Contributions are tax-deductible — reduces your taxable income.
B15: Withdrawals are taxed as income. Ideal for high-income earners.
B16: Unused room carries forward indefinitely.
... B36: © Your Personal Finance Coach | AI-Powered Finance Education | yourwebsite.ca
